Workbook

Sheet Budget
C2: Salary Budget and investment
C4: Monthly Salary | D4: 235000
C6: Monthly Budget
C8: Category | D8: Percentage | E8: Amount
C9: Essentials/Needs | D9: 0.3 | E9: =$D$4*D9 -> 70500
C10: Wants/Lifestyle | D10: 0.18 | E10: =$D$4*D10 -> 42300
C11: Savings and Investments | D11: 0.52 | E11: =$D$4*D11 -> 122200
C12: Emergency Fund (6 months of salary) | D12: 6 | E12: =$D$4*D12 -> 1410000
C14: Breakdown of Essentials/Needs (50%)
C15: Category | D15: Percentage | E15: Amount
C16: Rent and Utilities | D16: 0.4 | E16: =$D$4*D16*$D$9 -> 28200 | H16: =$D$9*D16 -> 0.12
C17: Groceries and Food | D17: 0.2 | E17: =$D$4*D17*$D$9 -> 14100 | H17: =$D$9*D17 -> 0.06
C18: Transportation | D18: 0.1 | E18: =$D$4*D18*$D$9 -> 7050 | H18: =$D$9*D18 -> 0.03
C19: Insurance and EMI | D19: 0.05 | E19: =$D$4*D19*$D$9 -> 3525 | H19: =$D$9*D19 -> 0.015
C20: Healthcare | D20: 0.08 | E20: =$D$4*D20*$D$9 -> 5640 | H20: =$D$9*D20 -> 0.024
C21: Other Essentials (CMA membership, etc.) | D21: 0.17 | E21: =$D$4*D21*$D$9 -> 11985 | H21: =$D$9*D21 -> 0.051
C23: Breakdown of wants / Lifestyle (30%)
C24: Category | D24: Percentage | E24: Amount
C25: Shopping | D25: 0.2 | E25: =$D$4*$D$10*D25 -> 8460 | H25: =$D$10*D25 -> 0.036
C26: Dining and Entertainment | D26: 0.1 | E26: =$D$4*$D$10*D26 -> 4230 | H26: =$D$10*D26 -> 0.018
C27: Subscription and Activities | D27: 0.1 | E27: =$D$4*$D$10*D27 -> 4230 | H27: =$D$10*D27 -> 0.018
C28: Travel & Holiday | D28: 0.55 | E28: =$D$4*$D$10*D28 -> 23265 | H28: =$D$10*D28 -> 0.099
C29: Miscellaneous wants | D29: 0.15 | E29: =$D$4*$D$10*D29 -> 6345 | H29: =$D$10*D29 -> 0.027
C31: Breakdown of Savings & Investments (20%)
C32: Category | D32: Percentage | E32: Amount
C33: Emergency Fund Contribution | D33: 0.25 | E33: =$D$4*$D$11*D33 -> 30550 | H33: =$D$11*D33 -> 0.13
C34: Retirement Planning | D34: 0.15 | E34: =$D$4*$D$11*D34 -> 18330 | H34: =$D$11*D34 -> 0.078
C35: Home Planning | D35: 0.4 | E35: =$D$4*$D$11*D35 -> 48880 | H35: =$D$11*D35 -> 0.208
C36: Equity/FD/MF | D36: 0.1 | E36: =$D$4*$D$11*D36 -> 12220 | H36: =$D$11*D36 -> 0.052
C37: Gold | D37: 0.1 | E37: =$D$4*$D$11*D37 -> 12220 | H37: =$D$11*D37 -> 0.052

Sheet Actual 2026
H2: Swati Salary | K2: Avinash Salary
H3: Total | I3: 150000 | K3: Total | L3: 180000
H4: To dad | I4: 50000 | K4: Expense | L4: =30000+15000 -> 45000 | N4: <<SAP Investments and Home Loan
H5: Contribution towards Family
I6: =I3-I4 -> 100000 | L6: =L3-L4 -> 135000
I7: =I6+L6 -> 235000
C9: Budgeted Allocation | K9: Actual Saved / Spent
B10: Year
B11: Month | C11: Jun | D11: Jul | E11: Aug | F11: Sep | G11: Oct | H11: Nov | I11: Dec | K11: Jun | L11: Jul | M11: Aug | N11: Sep | O11: Oct | P11: Nov | Q11: Dec
B13: Breakdown of Essentials/Needs (50%)
B14: Category
B15: Rent and Utilities | C15: =$I$7*Budget!H16 -> 28200
B16: Groceries and Food | C16: =$I$7*Budget!H17 -> 14100
B17: Transportation | C17: =$I$7*Budget!H18 -> 7050
B18: Insurance and EMI | C18: =$I$7*Budget!H19 -> 3525
B19: Healthcare | C19: =$I$7*Budget!H20 -> 5640
B20: Other Essentials | C20: =$I$7*Budget!H21 -> 11985
B22: Breakdown of wants / Lifestyle (30%)
B23: Category
B24: Shopping | C24: =$I$7*Budget!H25 -> 8460
B25: Dining and Entertainment | C25: =$I$7*Budget!H26 -> 4230
B26: Subscription and Activities | C26: =$I$7*Budget!H27 -> 4230
B27: Travel & Holiday | C27: =$I$7*Budget!H28 -> 23265
B28: Miscellaneous wants | C28: =$I$7*Budget!H29 -> 6345
B30: Breakdown of Savings & Investments (20%)
B31: Category
B32: Emergency Fund Contribution | C32: =$I$7*Budget!H33 -> 30550
B33: Parent's Outing planning | C33: =$I$7*Budget!H34 -> 18330
B34: Home Planning | C34: =$I$7*Budget!H35 -> 48880
B35: Other Investments | C35: =$I$7*Budget!H36 -> 12220
B36: Gold | C36: =$I$7*Budget!H37 -> 12220

Sheet Expense and Savings
B4: Accumulated Savings | E4: Saved | M4: Balance
E6: Jun | F6: Jul | G6: Aug | H6: Sep | I6: Oct | J6: Nov | K6: Dec
B7: For
C8: Rent and Utilities | E8: ='Actual 2026'!C15-'Expense and Savings'!E35 -> 1200 | F8: ='Actual 2026'!D15-'Expense and Savings'!F35 -> 0 | G8: ='Actual 2026'!E15-'Expense and Savings'!G35 -> 0 | H8: ='Actual 2026'!F15-'Expense and Savings'!H35 -> 0 | I8: ='Actual 2026'!G15-'Expense and Savings'!I35 -> 0 | J8: ='Actual 2026'!H15-'Expense and Savings'!J35 -> 0 | K8: ='Actual 2026'!I15-'Expense and Savings'!K35 -> 0 | M8: =SUM(E8:K8) -> 1200
C9: Groceries and Food | E9: ='Actual 2026'!C16-'Expense and Savings'!E36 -> 10600 | F9: ='Actual 2026'!D16-'Expense and Savings'!F36 -> 0 | G9: ='Actual 2026'!E16-'Expense and Savings'!G36 -> 0 | H9: ='Actual 2026'!F16-'Expense and Savings'!H36 -> 0 | I9: ='Actual 2026'!G16-'Expense and Savings'!I36 -> 0 | J9: ='Actual 2026'!H16-'Expense and Savings'!J36 -> 0 | K9: ='Actual 2026'!I16-'Expense and Savings'!K36 -> 0 | M9: =SUM(E9:K9) -> 10600
C10: Transportation | E10: ='Actual 2026'!C17-'Expense and Savings'!E37 -> 7050 | F10: ='Actual 2026'!D17-'Expense and Savings'!F37 -> 0 | G10: ='Actual 2026'!E17-'Expense and Savings'!G37 -> 0 | H10: ='Actual 2026'!F17-'Expense and Savings'!H37 -> 0 | I10: ='Actual 2026'!G17-'Expense and Savings'!I37 -> 0 | J10: ='Actual 2026'!H17-'Expense and Savings'!J37 -> 0 | K10: ='Actual 2026'!I17-'Expense and Savings'!K37 -> 0 | M10: =SUM(E10:K10) -> 7050
C11: Insurance and EMI | E11: ='Actual 2026'!C18-'Expense and Savings'!E38 -> -4275 | F11: ='Actual 2026'!D18-'Expense and Savings'!F38 -> 0 | G11: ='Actual 2026'!E18-'Expense and Savings'!G38 -> 0 | H11: ='Actual 2026'!F18-'Expense and Savings'!H38 -> 0 | I11: ='Actual 2026'!G18-'Expense and Savings'!I38 -> 0 | J11: ='Actual 2026'!H18-'Expense and Savings'!J38 -> 0 | K11: ='Actual 2026'!I18-'Expense and Savings'!K38 -> 0 | M11: =SUM(E11:K11) -> -4275
C12: Healthcare | E12: ='Actual 2026'!C19-'Expense and Savings'!E39 -> 4440 | F12: ='Actual 2026'!D19-'Expense and Savings'!F39 -> 0 | G12: ='Actual 2026'!E19-'Expense and Savings'!G39 -> 0 | H12: ='Actual 2026'!F19-'Expense and Savings'!H39 -> 0 | I12: ='Actual 2026'!G19-'Expense and Savings'!I39 -> 0 | J12: ='Actual 2026'!H19-'Expense and Savings'!J39 -> 0 | K12: ='Actual 2026'!I19-'Expense and Savings'!K39 -> 0 | M12: =SUM(E12:K12) -> 4440
C13: Other Essentials | E13: ='Actual 2026'!C20-'Expense and Savings'!E40 -> 11985 | F13: ='Actual 2026'!D20-'Expense and Savings'!F40 -> 0 | G13: ='Actual 2026'!E20-'Expense and Savings'!G40 -> 0 | H13: ='Actual 2026'!F20-'Expense and Savings'!H40 -> 0 | I13: ='Actual 2026'!G20-'Expense and Savings'!I40 -> 0 | J13: ='Actual 2026'!H20-'Expense and Savings'!J40 -> 0 | K13: ='Actual 2026'!I20-'Expense and Savings'!K40 -> 0 | M13: =SUM(E13:K13) -> 11985
B15: For
C16: Shopping | E16: ='Actual 2026'!C24-'Expense and Savings'!E43 -> 8460 | F16: ='Actual 2026'!D24-'Expense and Savings'!F43 -> 0 | G16: ='Actual 2026'!E24-'Expense and Savings'!G43 -> 0 | H16: ='Actual 2026'!F24-'Expense and Savings'!H43 -> 0 | I16: ='Actual 2026'!G24-'Expense and Savings'!I43 -> 0 | J16: ='Actual 2026'!H24-'Expense and Savings'!J43 -> 0 | K16: ='Actual 2026'!I24-'Expense and Savings'!K43 -> 0 | M16: =SUM(E16:K16) -> 8460
C17: Dining and Entertainment | E17: ='Actual 2026'!C25-'Expense and Savings'!E44 -> -770 | F17: ='Actual 2026'!D25-'Expense and Savings'!F44 -> 0 | G17: ='Actual 2026'!E25-'Expense and Savings'!G44 -> 0 | H17: ='Actual 2026'!F25-'Expense and Savings'!H44 -> 0 | I17: ='Actual 2026'!G25-'Expense and Savings'!I44 -> 0 | J17: ='Actual 2026'!H25-'Expense and Savings'!J44 -> 0 | K17: ='Actual 2026'!I25-'Expense and Savings'!K44 -> 0 | M17: =SUM(E17:K17) -> -770
C18: Activities | E18: ='Actual 2026'!C26-'Expense and Savings'!E45 -> 2330 | F18: ='Actual 2026'!D26-'Expense and Savings'!F45 -> 0 | G18: ='Actual 2026'!E26-'Expense and Savings'!G45 -> 0 | H18: ='Actual 2026'!F26-'Expense and Savings'!H45 -> 0 | I18: ='Actual 2026'!G26-'Expense and Savings'!I45 -> 0 | J18: ='Actual 2026'!H26-'Expense and Savings'!J45 -> 0 | K18: ='Actual 2026'!I26-'Expense and Savings'!K45 -> 0 | M18: =SUM(E18:K18) -> 2330
C19: Travel & Holiday | E19: ='Actual 2026'!C27-'Expense and Savings'!E46 -> 1265 | F19: ='Actual 2026'!D27-'Expense and Savings'!F46 -> 0 | G19: ='Actual 2026'!E27-'Expense and Savings'!G46 -> 0 | H19: ='Actual 2026'!F27-'Expense and Savings'!H46 -> 0 | I19: ='Actual 2026'!G27-'Expense and Savings'!I46 -> 0 | J19: ='Actual 2026'!H27-'Expense and Savings'!J46 -> 0 | K19: ='Actual 2026'!I27-'Expense and Savings'!K46 -> 0 | M19: =SUM(E19:K19) -> 1265
C20: Miscellaneous wants | E20: ='Actual 2026'!C28-'Expense and Savings'!E47 -> 6345 | F20: ='Actual 2026'!D28-'Expense and Savings'!F47 -> 0 | G20: ='Actual 2026'!E28-'Expense and Savings'!G47 -> 0 | H20: ='Actual 2026'!F28-'Expense and Savings'!H47 -> 0 | I20: ='Actual 2026'!G28-'Expense and Savings'!I47 -> 0 | J20: ='Actual 2026'!H28-'Expense and Savings'!J47 -> 0 | K20: ='Actual 2026'!I28-'Expense and Savings'!K47 -> 0 | M20: =SUM(E20:K20) -> 6345
B22: For
C23: Emergency Fund Contribution | E23: ='Detailed Expenses'!F67 -> 10000 | F23: ='Detailed Expenses'!G67 -> 0 | G23: ='Detailed Expenses'!H67 -> 0 | H23: ='Detailed Expenses'!I67 -> 0 | I23: ='Detailed Expenses'!J67 -> 0 | J23: ='Detailed Expenses'!K67 -> 0 | K23: ='Detailed Expenses'!L67 -> 0 | M23: =SUM(E23:K23) -> 10000
C24: Parent's Outing planning | E24: ='Detailed Expenses'!F70 -> 13000 | F24: ='Detailed Expenses'!G70 -> 0 | G24: ='Detailed Expenses'!H70 -> 0 | H24: ='Detailed Expenses'!I70 -> 0 | I24: ='Detailed Expenses'!J70 -> 0 | J24: ='Detailed Expenses'!K70 -> 0 | K24: ='Detailed Expenses'!L70 -> 0 | M24: =SUM(E24:K24) -> 13000
C25: Home Planning | E25: ='Detailed Expenses'!F73 -> 48880 | F25: ='Detailed Expenses'!G73 -> 0 | G25: ='Detailed Expenses'!H73 -> 0 | H25: ='Detailed Expenses'!I73 -> 0 | I25: ='Detailed Expenses'!J73 -> 0 | J25: ='Detailed Expenses'!K73 -> 0 | K25: ='Detailed Expenses'!L73 -> 0 | M25: =SUM(E25:K25) -> 48880
C26: Other Investments | E26: ='Detailed Expenses'!F76 -> 12220 | F26: ='Detailed Expenses'!G76 -> 0 | G26: ='Detailed Expenses'!H76 -> 0 | H26: ='Detailed Expenses'!I76 -> 0 | I26: ='Detailed Expenses'!J76 -> 0 | J26: ='Detailed Expenses'!K76 -> 0 | K26: ='Detailed Expenses'!L76 -> 0 | M26: =SUM(E26:K26) -> 12220
C27: Gold | E27: ='Detailed Expenses'!F79 -> 11000 | F27: ='Detailed Expenses'!G79 -> 0 | G27: ='Detailed Expenses'!H79 -> 0 | H27: ='Detailed Expenses'!I79 -> 0 | I27: ='Detailed Expenses'!J79 -> 0 | J27: ='Detailed Expenses'!K79 -> 0 | K27: ='Detailed Expenses'!L79 -> 0 | M27: =SUM(E27:K27) -> 11000
B32: Monthly Expenses | E32: Spent | M32: Balance
B34: For | E34: Jun | F34: Jul | G34: Aug | H34: Sep | I34: Oct | J34: Nov | K34: Dec
C35: Rent and Utilities | E35: ='Detailed Expenses'!F11 -> 27000 | F35: ='Detailed Expenses'!G11 -> 0 | G35: ='Detailed Expenses'!H11 -> 0 | H35: ='Detailed Expenses'!I11 -> 0 | I35: ='Detailed Expenses'!J11 -> 0 | J35: ='Detailed Expenses'!K11 -> 0 | K35: ='Detailed Expenses'!L11 -> 0 | M35: =SUM(E35:K35) -> 27000
C36: Groceries and Food | E36: ='Detailed Expenses'!F18 -> 3500 | F36: ='Detailed Expenses'!G18 -> 0 | G36: ='Detailed Expenses'!H18 -> 0 | H36: ='Detailed Expenses'!I18 -> 0 | I36: ='Detailed Expenses'!J18 -> 0 | J36: ='Detailed Expenses'!K18 -> 0 | K36: ='Detailed Expenses'!L18 -> 0 | M36: =SUM(E36:K36) -> 3500
C37: Transportation | E37: ='Detailed Expenses'!F24 -> 0 | F37: ='Detailed Expenses'!G24 -> 0 | G37: ='Detailed Expenses'!H24 -> 0 | H37: ='Detailed Expenses'!I24 -> 0 | I37: ='Detailed Expenses'!J24 -> 0 | J37: ='Detailed Expenses'!K24 -> 0 | K37: ='Detailed Expenses'!L24 -> 0 | M37: =SUM(E37:K37) -> 0
C38: Insurance and EMI | E38: ='Detailed Expenses'!F28 -> 7800 | F38: ='Detailed Expenses'!G28 -> 0 | G38: ='Detailed Expenses'!H28 -> 0 | H38: ='Detailed Expenses'!I28 -> 0 | I38: ='Detailed Expenses'!J28 -> 0 | J38: ='Detailed Expenses'!K28 -> 0 | K38: ='Detailed Expenses'!L28 -> 0 | M38: =SUM(E38:K38) -> 7800
C39: Healthcare | E39: ='Detailed Expenses'!F32 -> 1200 | F39: ='Detailed Expenses'!G32 -> 0 | G39: ='Detailed Expenses'!H32 -> 0 | H39: ='Detailed Expenses'!I32 -> 0 | I39: ='Detailed Expenses'!J32 -> 0 | J39: ='Detailed Expenses'!K32 -> 0 | K39: ='Detailed Expenses'!L32 -> 0 | M39: =SUM(E39:K39) -> 1200
C40: Other Essentials | E40: ='Detailed Expenses'!F36 -> 0 | F40: ='Detailed Expenses'!G36 -> 0 | G40: ='Detailed Expenses'!H36 -> 0 | H40: ='Detailed Expenses'!I36 -> 0 | I40: ='Detailed Expenses'!J36 -> 0 | J40: ='Detailed Expenses'!K36 -> 0 | K40: ='Detailed Expenses'!L36 -> 0 | M40: =SUM(E40:K40) -> 0
B42: For
C43: Shopping | E43: ='Detailed Expenses'!F42 -> 0 | F43: ='Detailed Expenses'!G42 -> 0 | G43: ='Detailed Expenses'!H42 -> 0 | H43: ='Detailed Expenses'!I42 -> 0 | I43: ='Detailed Expenses'!J42 -> 0 | J43: ='Detailed Expenses'!K42 -> 0 | K43: ='Detailed Expenses'!L42 -> 0 | M43: =SUM(E43:K43) -> 0
C44: Dining and Entertainment | E44: ='Detailed Expenses'!F46 -> 5000 | F44: ='Detailed Expenses'!G46 -> 0 | G44: ='Detailed Expenses'!H46 -> 0 | H44: ='Detailed Expenses'!I46 -> 0 | I44: ='Detailed Expenses'!J46 -> 0 | J44: ='Detailed Expenses'!K46 -> 0 | K44: ='Detailed Expenses'!L46 -> 0 | M44: =SUM(E44:K44) -> 5000
C45: Subscription and Activities | E45: ='Detailed Expenses'!F54 -> 1900 | F45: ='Detailed Expenses'!G54 -> 0 | G45: ='Detailed Expenses'!H54 -> 0 | H45: ='Detailed Expenses'!I54 -> 0 | I45: ='Detailed Expenses'!J54 -> 0 | J45: ='Detailed Expenses'!K54 -> 0 | K45: ='Detailed Expenses'!L54 -> 0 | M45: =SUM(E45:K45) -> 1900
C46: Travel & Holiday | E46: ='Detailed Expenses'!F58 -> 22000 | F46: ='Detailed Expenses'!G58 -> 0 | G46: ='Detailed Expenses'!H58 -> 0 | H46: ='Detailed Expenses'!I58 -> 0 | I46: ='Detailed Expenses'!J58 -> 0 | J46: ='Detailed Expenses'!K58 -> 0 | K46: ='Detailed Expenses'!L58 -> 0 | M46: =SUM(E46:K46) -> 22000
C47: Miscellaneous wants | E47: ='Detailed Expenses'!F62 -> 0 | F47: ='Detailed Expenses'!G62 -> 0 | G47: ='Detailed Expenses'!H62 -> 0 | H47: ='Detailed Expenses'!I62 -> 0 | I47: ='Detailed Expenses'!J62 -> 0 | J47: ='Detailed Expenses'!K62 -> 0 | K47: ='Detailed Expenses'!L62 -> 0 | M47: =SUM(E47:K47) -> 0

Sheet Detailed Expenses
F3: 2026
F4: Jun | G4: Jul | H4: Aug | I4: Sep | J4: Oct | K4: Nov | L4: Dec | M4: Excess Saved/ Overspent
B5: Breakdown of Essentials/Needs (50%)
B6: Category
B7: Rent and Utilities | E7: Budgeted | F7: ='Actual 2026'!C15 -> 28200 | G7: ='Actual 2026'!D15 -> 0 | H7: ='Actual 2026'!E15 -> 0 | I7: ='Actual 2026'!F15 -> 0 | J7: ='Actual 2026'!G15 -> 0 | K7: ='Actual 2026'!H15 -> 0 | L7: ='Actual 2026'!I15 -> 0
C8: Rent | E8: Actual | F8: =27000-F10 -> 22500
C9: Electricity - after 11th of every month
C10: Maintenance | F10: 4500
C11: Total | F11: =SUM(F8:F10) -> 27000 | G11: =SUM(G8:G10) -> 0 | H11: =SUM(H8:H10) -> 0 | I11: =SUM(I8:I10) -> 0 | J11: =SUM(J8:J10) -> 0 | K11: =SUM(K8:K10) -> 0 | L11: =SUM(L8:L10) -> 0 | M11: =SUM(F7:L7)-SUM(F11:L11) -> 1200
B12: Groceries and Food | E12: Budgeted | F12: ='Actual 2026'!C16 -> 14100 | G12: ='Actual 2026'!D16 -> 0 | H12: ='Actual 2026'!E16 -> 0 | I12: ='Actual 2026'!F16 -> 0 | J12: ='Actual 2026'!G16 -> 0 | K12: ='Actual 2026'!H16 -> 0 | L12: ='Actual 2026'!I16 -> 0
C13: Groceries | E13: Actual | F13: 2000
C14: Vegetables | F14: 500
C15: Fruits | F15: 1000
C16: When ordered Online
C17: Non-Veg
C18: Total | F18: =SUM(F13:F17) -> 3500 | G18: =SUM(G13:G17) -> 0 | H18: =SUM(H13:H17) -> 0 | I18: =SUM(I13:I17) -> 0 | J18: =SUM(J13:J17) -> 0 | K18: =SUM(K13:K17) -> 0 | L18: =SUM(L13:L17) -> 0 | M18: =SUM(F12:L12)-SUM(F18:L18) -> 10600
B19: Transportation | E19: Budgeted | F19: ='Actual 2026'!C17 -> 7050 | G19: ='Actual 2026'!D17 -> 0 | H19: ='Actual 2026'!E17 -> 0 | I19: ='Actual 2026'!F17 -> 0 | J19: ='Actual 2026'!G17 -> 0 | K19: ='Actual 2026'!H17 -> 0 | L19: ='Actual 2026'!I17 -> 0
C20: Metro | E20: Actual
C21: Cab
C22: Auto
C23: Train
C24: Total | F24: =SUM(F20:F23) -> 0 | G24: =SUM(G20:G23) -> 0 | H24: =SUM(H20:H23) -> 0 | I24: =SUM(I20:I23) -> 0 | J24: =SUM(J20:J23) -> 0 | K24: =SUM(K20:K23) -> 0 | L24: =SUM(L20:L23) -> 0 | M24: =SUM(F19:L19)-SUM(F24:L24) -> 7050
B25: Insurance and EMI | E25: Budgeted | F25: ='Actual 2026'!C18 -> 3525 | G25: ='Actual 2026'!D18 -> 0 | H25: ='Actual 2026'!E18 -> 0 | I25: ='Actual 2026'!F18 -> 0 | J25: ='Actual 2026'!G18 -> 0 | K25: ='Actual 2026'!H18 -> 0 | L25: ='Actual 2026'!I18 -> 0
C26: EMI | E26: Actual | F26: 6800
C27: Insurance | F27: 1000
C28: Total | F28: =SUM(F26:F27) -> 7800 | G28: =SUM(G26:G27) -> 0 | H28: =SUM(H26:H27) -> 0 | I28: =SUM(I26:I27) -> 0 | J28: =SUM(J26:J27) -> 0 | K28: =SUM(K26:K27) -> 0 | L28: =SUM(L26:L27) -> 0 | M28: =SUM(F25:L25)-SUM(F28:L28) -> -4275
B29: Healthcare | E29: Budgeted | F29: ='Actual 2026'!C19 -> 5640 | G29: ='Actual 2026'!D19 -> 0 | H29: ='Actual 2026'!E19 -> 0 | I29: ='Actual 2026'!F19 -> 0 | J29: ='Actual 2026'!G19 -> 0 | K29: ='Actual 2026'!H19 -> 0 | L29: ='Actual 2026'!I19 -> 0
C30: Hospital | E30: Actual
C31: Medicines | F31: 1200
C32: Total | F32: =SUM(F30:F31) -> 1200 | G32: =SUM(G30:G31) -> 0 | H32: =SUM(H30:H31) -> 0 | I32: =SUM(I30:I31) -> 0 | J32: =SUM(J30:J31) -> 0 | K32: =SUM(K30:K31) -> 0 | L32: =SUM(L30:L31) -> 0 | M32: =SUM(F29:L29)-SUM(F32:L32) -> 4440
B33: Other Essentials | E33: Budgeted | F33: ='Actual 2026'!C20 -> 11985 | G33: ='Actual 2026'!D20 -> 0 | H33: ='Actual 2026'!E20 -> 0 | I33: ='Actual 2026'!F20 -> 0 | J33: ='Actual 2026'!G20 -> 0 | K33: ='Actual 2026'!H20 -> 0 | L33: ='Actual 2026'!I20 -> 0
E34: Actual
C36: Total | F36: =SUM(F34:F35) -> 0 | G36: =SUM(G34:G35) -> 0 | H36: =SUM(H34:H35) -> 0 | I36: =SUM(I34:I35) -> 0 | J36: =SUM(J34:J35) -> 0 | K36: =SUM(K34:K35) -> 0 | L36: =SUM(L34:L35) -> 0 | M36: =SUM(F33:L33)-SUM(F36:L36) -> 11985
B37: Breakdown of wants / Lifestyle (30%)
B38: Category
B39: Shopping | E39: Budgeted | F39: ='Actual 2026'!C24 -> 8460 | G39: ='Actual 2026'!D24 -> 0 | H39: ='Actual 2026'!E24 -> 0 | I39: ='Actual 2026'!F24 -> 0 | J39: ='Actual 2026'!G24 -> 0 | K39: ='Actual 2026'!H24 -> 0 | L39: ='Actual 2026'!I24 -> 0
C40: Self
C41: For relatives
C42: Total | F42: =SUM(F40:F41) -> 0 | G42: =SUM(G40:G41) -> 0 | H42: =SUM(H40:H41) -> 0 | I42: =SUM(I40:I41) -> 0 | J42: =SUM(J40:J41) -> 0 | K42: =SUM(K40:K41) -> 0 | L42: =SUM(L40:L41) -> 0 | M42: =SUM(F39:L39)-SUM(F42:L42) -> 8460
B43: Dining and Entertainment | E43: Budgeted | F43: ='Actual 2026'!C25 -> 4230 | G43: ='Actual 2026'!D25 -> 0 | H43: ='Actual 2026'!E25 -> 0 | I43: ='Actual 2026'!F25 -> 0 | J43: ='Actual 2026'!G25 -> 0 | K43: ='Actual 2026'!H25 -> 0 | L43: ='Actual 2026'!I25 -> 0
...

Sheet Sheet5
B3: Rent and Utilities
C4: Rent
C5: Electricity - after 11th of every month
C6: Maintenance
C7: Total
B8: Groceries and Food
C9: Groceries
C10: Vegetables
C11: Fruits
C12: When ordered Online
C13: Non-Veg
C14: Total
B15: Transportation
C16: Metro
C17: Cab
C18: Auto
C19: Train
C20: Total
B21: Insurance and EMI
C22: EMI
C23: Insurance
C24: Total
B25: Healthcare
C26: Hospital
C27: Medicines
C28: Total
B29: Other Essentials
C32: Total
B35: Shopping
C36: Self
C37: For relatives
C38: Total
B39: Dining and Entertainment
C40: Movies
C41: Restuarants
C42: Total
B43: Subscription and Activities
C44: Timezone / Playzone
C45: Subscriptions
C50: Total
...
